Workbook
Name WEL: 'Fire Pump Test Data'!$L$1

Sheet Fire Pump Test Data
G2: 2005 Dr. Martin Luther King Jr. Dr.
G3: Indianapolis, IN 46202
G4: (317) 925-9661
G6: www.PeerlessPump.com
A8: Project Name: | D8: Home Depot 0526 Corpus Christi TX | Q8: Address: | R8: 5041 S Padre Island Dr
A9: Project Description | D9: Electric Splt Case | M9: Serial No. | N9: 9927226906 | R9: Corpus Christi, Texas 78411
A10: City - State - Zip | D10: Corpus Christi, Texas 78411 | M10: Start-up Date: | N10: 46079
A12: Fire Pump Flow Test Data
A13: 1. | B13: Pump / Driver / Controller | Q13: Driver Rep. | S13: Michael Phears
A15: General Contractor | I15: Peerless Rep. | L15: Michael Phears | Q15: Controller Rep. | S15: Michael Phears
E16: ph. | M16: ph. | N16: 281-772-6451
A17: Insurance / Fire Department Rep. | F17: Corpus Fire Dept | I17: Jockey Pump Start PSI | N17: 160 | Q17: Auto Start | T17: 6
A18: Brian Rogers | E18: ph. | F18: 361-739-3545 | I18: Jockey Pump Stop PSI | N18: 170 | Q18: Manual Start | T18: 6
A19: Sprinkler Contractor | E19: Western States | I19: Fire Pump Start PSI | N19: 150 | Q19: Timer Setting | T19: n/a
A20: Adam | E20: ph. | I20: Fire Pump Stop PSI | N20: 160 | Q20: Transfer Switch | T20: n/a
A21: Engineering Firm Rep. | I21: Automatic Operator Work | N21: yes | Q21: Suction Size | T21: 8
E22: ph. | I22: Manual Operator Work | N22: yes | Q22: Discharge Size | T22: 6
C24: PUMP | J24: DRIVER | P24: CONTROLLER
A25: Pump Type | E25: Split Case | G25: Driver Type | K25: Electric | N25: Controller Type | R25: Electric
A26: Pump Manufacturer | E26: Peerless | G26: Driver Manufacturer | K26: Weg | N26: Controller Manufacturer | R26: Firetrol
A27: Pump Serial Number | E27: 50028220 | G27: Driver Serial Number | K27: 11166711194 | N27: Controller Serial Number | R27: FZ1258856
A28: Pump Model Number | E28: 6AEF10 | G28: Driver Model Number | K28: 125360P3EFP404TS-W40 | N28: Controller Model Number | R28: FTA1930-AM125B
A29: Pump Rated GPM | E29: 1500 | G29: Driver Horse Power | K29: 125 | N29: Controller Horse Power | R29: 125
A30: Pump Rated PSI | E30: 110 | G30: Driver RPM | K30: 3545 | N30: Controller Volts | R30: 460
A31: Pump Rated RPM | E31: 3550 | G31: Driver Volts | K31: 230/460 | N31: Controller Phase | R31: 3
A32: Pump Maximum PSI | E32: 138 | G32: Driver Amps | K32: 274/137 | N32: Controller Cycles | R32: 60
A33: Pump Pressure at 150% | E33: 80 | G33: Driver Phase | K33: 3 | N33: Controller Interrupt Cap
A34: Pump Impeller Size | E34: 8.29 | G34: Driver Cycles | K34: 60 | N34: Controller Diesel Volts | R34: n/a
A35: Pump Stages | E35: 1 | G35: Driver Service Factor | K35: 1.15 | N35: Controller Diesel Ground | R35: n/a
B37: FIRE PUMP TEST DATA
A39: Speed | C39: Suction | E39: Discharge | G39: Net | L39: Streams | Q39: Total | S39: % | T39: Volts | U39: Amps
A40: Rpm | C40: Pressure | E40: Pressure | G40: Head | I40: Size | K40: Pitot Readings | Q40: GPM | S40: Rated
C41: Psi | E41: Psi | G41: Psi | J41: #1 | K41: #2 | L41: #3 | M41: #4 | N41: #5 | O41: #6 | P41: #7 | S41: Capacity
A42: 3574 | C42: 52 | E42: 192 | G42: =IF(E42="","",E42-C42) -> 140 | I42: 2.5 | J42: CHURN | Q42: 0 | S42: 0
A43: 3560 | C43: 34 | E43: 144 | G43: =IF(E43="","",E43-C43) -> 110 | I43: 2.5 | J43: 5 | K43: 5 | L43: 5 | Q43: =IF(I43="","",'Acceptance Test Curve'!$L$10) -> 1522.0542 | S43: =IF(I43="","",+Q43/$E$29) -> 1.0147028
A44: 3555 | C44: 15 | E44: 96 | G44: =IF(E44="","",E44-C44) -> 81 | I44: 2.5 | J44: 11 | K44: 11 | L44: 11 | Q44: =IF(I44="","",'Acceptance Test Curve'!$L$11) -> 2257.5711 | S44: =IF(I44="","",+Q44/$E$29) -> 1.5050474
G45: =IF(E45="","",E45-C45) | I45: 2.5 | Q45: =IF(I45="","",'Acceptance Test Curve'!$L$12) -> 0 | S45: =IF(I45="","",+Q45/$E$29) -> 0
G46: =IF(E46="","",E46-C46) | I46: 2.5 | Q46: =IF(I46="","",'Acceptance Test Curve'!$L$13) -> 0 | S46: =IF(I46="","",+Q46/$E$29) -> 0
G47: =IF(E47="","",E47-C47) | Q47: =IF(I47="","",'Acceptance Test Curve'!$L$14) | S47: =IF(I47="","",+Q47/$E$29)
A48: Readings Marked (+) in Shaded Column are Heads Above Atmosphere. Those Marked (-) are Lifts. For Vertical Shaft Pumps omit Suction Pressure and Net Head Readings.
...

Sheet Acceptance Test Curve
A1: Project: | B1: ='Fire Pump Test Data'!D8 -> Home Depot 0526 Corpus Christi TX | F1: FIRE PUMP TEST RESULTS ON NET BASIS | Z1: gpm | AA1: psi
A2: Location: | B2: ='Fire Pump Test Data'!D10 -> Corpus Christi, Texas 78411 | F2: Pump ID: | H2: ='Fire Pump Test Data'!$E$25 -> Split Case | L2: Rated Flow: | M2: ='Fire Pump Test Data'!$E$29 -> 1500 | N2: Rated Pressure: | P2: ='Fire Pump Test Data'!$E$30 -> 110 | Q2: Rated Speed: | S2: ='Fire Pump Test Data'!$E$31 -> 3550 | T2: Suction Size(in.): | V2: ='Fire Pump Test Data'!$T$21 -> 8 | Y2: Churn Rating | Z2: 0 | AA2: =+P2*1.2 -> 132
F3: Make: | H3: ='Fire Pump Test Data'!$E$26 -> Peerless | L3: Model: | M3: ='Fire Pump Test Data'!$E$28 -> 6AEF10 | P3: Serial No.: | Q3: ='Fire Pump Test Data'!$E$27 -> 50028220 | T3: Discharge Size(in.): | V3: ='Fire Pump Test Data'!$T$22 -> 6 | Y3: 100% Rating | Z3: =+M2 -> 1500 | AA3: =P2*1 -> 110
Y4: 150% Rating | Z4: =+M2*1.5 -> 2250 | AA4: =+P2*0.65 -> 71.5
A5: Pump | B5: Flowing | K5: Flow- | L5: Combined | M5: Pressure | O5: Vel. | P5: Net | Q5: Pump | R5: Corr. to Rated Speed
A6: Test | B6: Outlet I.D.* | C6: Cd* | K6: meter | L6: Flow | M6: Suction | N6: Discharge | O6: Head | P6: Pressure | Q6: Speed | R6: Flow | S6: Pressure | T6: Volts | U6: Amps
A7: Date | B7: (i.e.1 1/8"=1.125") | D7: Pitot Readings* - (psi) | K7: (gpm) | L7: (gpm) | M7: (psi) | N7: (psi) | O7: Corr. | P7: (psi) | Q7: (rpm) | R7: (gpm) | S7: (psi) | T7: (v) | U7: (A)
B9: ='Fire Pump Test Data'!$I$42 -> 2.5 | C9: 1.217 | D9: ='Fire Pump Test Data'!$J$42 -> CHURN | E9: ='Fire Pump Test Data'!$K$42 -> 0 | F9: ='Fire Pump Test Data'!$L$42 -> 0 | G9: ='Fire Pump Test Data'!$M$42 -> 0 | H9: ='Fire Pump Test Data'!$N$42 -> 0 | I9: ='Fire Pump Test Data'!$O$42 -> 0 | J9: ='Fire Pump Test Data'!$P$42 -> 0 | K9: 0 | L9: 0 | M9: ='Fire Pump Test Data'!$C$42 -> 52 | N9: ='Fire Pump Test Data'!$E$42 -> 192 | O9: =0.001123*(L9^2)*((1/$V$3^4)-(1/$V$2^4)) -> 0 | P9: =+N9-M9+O9 -> 140 | Q9: ='Fire Pump Test Data'!$A$42 -> 3574 | R9: =IF(Q9=0,"",+L9*($S$2/Q9)) -> 0 | S9: =IF(Q9=0,"",+P9*($S$2/Q9)^2) -> 138.12607 | T9: ='Fire Pump Test Data'!$T$42 -> 0 | U9: ='Fire Pump Test Data'!$U$42 -> 0
B10: ='Fire Pump Test Data'!$I$43 -> 2.5 | C10: 1.217 | D10: ='Fire Pump Test Data'!$J$43 -> 5 | E10: ='Fire Pump Test Data'!$K$43 -> 5 | F10: ='Fire Pump Test Data'!$L$43 -> 5 | G10: ='Fire Pump Test Data'!$M$43 -> 0 | H10: ='Fire Pump Test Data'!$N$43 -> 0 | I10: ='Fire Pump Test Data'!$O$43 -> 0 | J10: ='Fire Pump Test Data'!$P$43 -> 0 | K10: 0 | L10: =29.83*C10*B10^2*D10^0.5+29.83*C10*B10^2*E10^0.5+29.83*C10*B10^2*F10^0.5+29.83*C10*B10^2*G10^0.5+29.83*C10*B10^2*H10^0.5+29.35*C10*B10^2*I10^0.5+29.83*C10*B10^2*J10^0.5+K10 -> 1522.0542 | M10: ='Fire Pump Test Data'!$C$43 -> 34 | N10: ='Fire Pump Test Data'!$E$43 -> 144 | O10: =0.001123*(L10^2)*((1/$V$3^4)-(1/$V$2^4)) -> 1.3722494 | P10: =+N10-M10+O10 -> 111.37225 | Q10: ='Fire Pump Test Data'!$A$43 -> 3560 | R10: =IF(Q10=0,"",+L10*($S$2/Q10)) -> 1517.7787 | S10: =IF(Q10=0,"",+P10*($S$2/Q10)^2) -> 110.74744 | T10: ='Fire Pump Test Data'!$T$43 -> 0 | U10: ='Fire Pump Test Data'!$U$43 -> 0
B11: ='Fire Pump Test Data'!$I$44 -> 2.5 | C11: 1.217 | D11: ='Fire Pump Test Data'!$J$44 -> 11 | E11: ='Fire Pump Test Data'!$K$44 -> 11 | F11: ='Fire Pump Test Data'!$L$44 -> 11 | G11: ='Fire Pump Test Data'!$M$44 -> 0 | H11: ='Fire Pump Test Data'!$N$44 -> 0 | I11: ='Fire Pump Test Data'!$O$44 -> 0 | J11: ='Fire Pump Test Data'!$P$44 -> 0 | K11: 0 | L11: =29.83*C11*B11^2*D11^0.5+29.83*C11*B11^2*E11^0.5+29.83*C11*B11^2*F11^0.5+29.83*C11*B11^2*G11^0.5+29.83*C11*B11^2*H11^0.5+29.83*C11*B11^2*I11^0.5+29.83*C11*B11^2*J11^0.5+K11 -> 2257.5711 | M11: ='Fire Pump Test Data'!$C$44 -> 15 | N11: ='Fire Pump Test Data'!$E$44 -> 96 | O11: =0.001123*(L11^2)*((1/$V$3^4)-(1/$V$2^4)) -> 3.0189487 | P11: =+N11-M11+O11 -> 84.018949 | Q11: ='Fire Pump Test Data'!$A$44 -> 3555 | R11: =IF(Q11=0,"",+L11*($S$2/Q11)) -> 2254.3959 | S11: =IF(Q11=0,"",+P11*($S$2/Q11)^2) -> 83.782775 | T11: ='Fire Pump Test Data'!$T$44 -> 0 | U11: ='Fire Pump Test Data'!$U$44 -> 0
B12: ='Fire Pump Test Data'!$I$45 -> 2.5 | C12: 1.217 | P12: =+N12-M12+O12 -> 0 | Q12: ='Fire Pump Test Data'!$A$45 -> 0 | R12: =IF(Q12=0,"",+L12*($S$2/Q12)) | S12: =IF(Q12=0,"",+P12*($S$2/Q12)^2) | T12: ='Fire Pump Test Data'!$T$45 -> 0 | U12: ='Fire Pump Test Data'!$U$45 -> 0
B13: ='Fire Pump Test Data'!$I$46 -> 2.5 | C13: 1.217 | O13: =IF(L13="","",(0.001123*(L13^2)*((1/$V$3^4)-(1/$V$2^4)))) | P13: =IF(B13=0,P12,(+N13-M13+O13)) -> #VALUE! | Q13: ='Fire Pump Test Data'!$A$46 -> 0 | R13: =IF(Q13=0,"",+L13*($S$2/Q13)) | S13: =IF(Q13=0,"",+P13*($S$2/Q13)^2) | T13: ='Fire Pump Test Data'!$T$45 -> 0 | U13: ='Fire Pump Test Data'!$U$45 -> 0
B14: ='Fire Pump Test Data'!$I$47 -> 0 | C14: 1.217 | P14: =IF(B14=0,P13,(+N14-M14+O14)) -> #VALUE! | Q14: ='Fire Pump Test Data'!$A$47 -> 0 | R14: =IF(Q14=0,"",+L14*($S$2/Q14)) | S14: =IF(Q14=0,"",+P14*($S$2/Q14)^2) | T14: ='Fire Pump Test Data'!$T$45 -> 0 | U14: ='Fire Pump Test Data'!$U$45 -> 0
A16: *NOTE: Flowing Outlet I.D. must be 1.125", 1.75" or 2.5". The conversion of pitot readings to a flowrate is automatic based on Cd of Underwriter's Playpipes for 1.125" & 1.75" or a Cd of smooth, rounded 2.5" outlet.

Sheet Field Data Sheet
A1: Speed | B1: Suction | C1: Discharge | D1: Dia | E1: Pitot Pressure | I1: Flow | J1: Volts | M1: Amps
D2: 2.50 | E2: CHURN | I2: 0
D3: 2.50
D4: 2.50
E9: Engine | F9: Full Load | L9: % | M9: GPM | N9: Pito PSI | O9: TDH
A10: Jockey Pump Start: | E10: RPM | L10: Churn | M10: 0 | N10: 0 | O10: 138
A11: Jockey Pump Stop: | E11: Oil Press | H11: Starts | L11: 100 | M11: 1509 | N11: 3@5 | O11: 110
E12: Temp | H12: Manual | I12: Auto | L12: 150 | M12: 2259 | N12: 3@11 | O12: 80 | P12: 0r 2248 | Q12: 4@6.14
A13: Fire Pump Stop: | E13: Damper T
E14: Final Hour
E16: Bearing | F16: Temp
A17: NOTES: | E17: Start | F17: Stop
D18: Indoard
D19: Outboard

Sheet Revison Log
A1: Revision Number | B1: Changes
A2: 1 | B2: Changed formual references to named values.
B3: Added additional data fields.
A4: 2.0 | B4: Removed all that stuff.
